Test symbolic argv:
  $ explode-js exploit test_sink_argv.js
  "":83050.2-83050.20: Assert failure:
   Stmt: assert (hd params)
   Expr: false
  Found 1 problems!
    replaying : test_sink_argv.js...
      running : _results/test_sink_argv/test-suite/witness-0.json
       status : false (no side effect).

Test eval and Function explode:
  $ explode-js exploit test_sink_eval.js
  Eval failure: source
  Found 1 problems!
    replaying : test_sink_eval.js...
      running : _results/test_sink_eval/test-suite/witness-0.json
       status : true ("success" in stdout)
      running : _results/test_sink_eval/test-suite/witness-1.json
       status : true ("success" in stdout)
      running : _results/test_sink_eval/test-suite/witness-2.json
       status : true ("success" in stdout)
  $ explode-js exploit test_sink_Function.js
  Eval failure: body
  Found 1 problems!
    replaying : test_sink_Function.js...
      running : _results/test_sink_Function/test-suite/witness-0.json
       status : false (no side effect).
      running : _results/test_sink_Function/test-suite/witness-1.json
       status : false (no side effect).
      running : _results/test_sink_Function/test-suite/witness-2.json
       status : false (no side effect).

Test exec explode:
  $ explode-js exploit test_sink_exec.js
  Exec failure: (str.++ ("git fetch ", remote))
  Found 1 problems!
    replaying : test_sink_exec.js...
      running : _results/test_sink_exec/test-suite/witness-0.json
       status : true (created file "success")
Test readFile explode
  $ explode-js exploit test_sink_fs.js
  ReadFile failure: source
  Found 1 problems!
    replaying : test_sink_fs.js...
      running : _results/test_sink_fs/test-suite/witness-0.json
       status : true (undesired file access occurred)

Test polluted explode:
  $ explode-js exploit test_pollution_1.js
  - : app = { "__completion__": true, "value": "polluted",
              "type": symbol("normal"), "target": symbol("empty"),  }
  All Ok!
    replaying : test_pollution_1.js...
  $ explode-js exploit test_pollution_2.js
  Abort: "Prototype pollution detected!"
  Found 1 problems!
    replaying : test_pollution_2.js...
      running : _results/test_pollution_2/test-suite/witness-0.json
       status : true ("polluted" in stdout)
  $ explode-js exploit test_pollution_3.js
  Abort: "Prototype pollution detected!"
  Found 1 problems!
    replaying : test_pollution_3.js...
      running : _results/test_pollution_3/test-suite/witness-0.json
       status : true ("polluted" in stdout)
  $ explode-js exploit test_pollution_4.js
  "Uncaught TypeError"
  "Uncaught TypeError"
  "Uncaught TypeError"
  "Uncaught TypeError"
  "Uncaught TypeError"
  "Uncaught TypeError"
  "Uncaught TypeError"
        abort : "Uncaught Error: I pollute."
  Found 1 problems!
    replaying : test_pollution_4.js...
      running : _results/test_pollution_4/test-suite/witness-0.json
       status : true (threw Error("I pollute."))
  unexpected node failure: /home/filipe/projects/explode-js/_build/default/test/test_pollution_4.js:52
    throw Error("I pollute.");
    ^

  Error: I pollute.
      at Object.<anonymous> (/home/filipe/projects/explode-js/_build/default/test/test_pollution_4.js:52:9)
      at Module._compile (node:internal/modules/cjs/loader:1356:14)
      at Module._extensions..js (node:internal/modules/cjs/loader:1414:10)
      at Module.load (node:internal/modules/cjs/loader:1197:32)
      at Module._load (node:internal/modules/cjs/loader:1013:12)
      at Function.executeUserEntryPoint [as runMain] (node:internal/modules/run_main:128:12)
      at node:internal/main/run_main_module:28:49

  Node.js v18.19.1
